Running on euler with following parameters : 
User : atabin
Model : segnet
Data folder : /cluster/work/igp_psr/ai4good/group-1b/data/
Saving directory : /cluster/scratch/atabin/segnet/
Checkpoint path : /cluster/scratch/atabin/checkpoints/segnet/
Downloading: "https://download.pytorch.org/models/vgg16_bn-6c64b313.pth" to /cluster/home/atabin/.cache/torch/hub/checkpoints/vgg16_bn-6c64b313.pth
{'model': 'segnet', 'data_dir': '/cluster/work/igp_psr/ai4good/group-1b/data/', 'checkpoint_path': '/cluster/scratch/atabin/checkpoints/segnet/', 'save_dir': '/cluster/scratch/atabin/segnet/'}
Running segnet...
Traceback (most recent call last):
  File "/cluster/home/atabin/miniconda3/envs/climatenet/lib/python3.8/urllib/request.py", line 1350, in do_open
    h.request(req.get_method(), req.selector, req.data, headers,
  File "/cluster/home/atabin/miniconda3/envs/climatenet/lib/python3.8/http/client.py", line 1255, in request
    self._send_request(method, url, body, headers, encode_chunked)
  File "/cluster/home/atabin/miniconda3/envs/climatenet/lib/python3.8/http/client.py", line 1301, in _send_request
    self.endheaders(body, encode_chunked=encode_chunked)
  File "/cluster/home/atabin/miniconda3/envs/climatenet/lib/python3.8/http/client.py", line 1250, in endheaders
    self._send_output(message_body, encode_chunked=encode_chunked)
  File "/cluster/home/atabin/miniconda3/envs/climatenet/lib/python3.8/http/client.py", line 1010, in _send_output
    self.send(msg)
  File "/cluster/home/atabin/miniconda3/envs/climatenet/lib/python3.8/http/client.py", line 950, in send
    self.connect()
  File "/cluster/home/atabin/miniconda3/envs/climatenet/lib/python3.8/http/client.py", line 1417, in connect
    super().connect()
  File "/cluster/home/atabin/miniconda3/envs/climatenet/lib/python3.8/http/client.py", line 921, in connect
    self.sock = self._create_connection(
  File "/cluster/home/atabin/miniconda3/envs/climatenet/lib/python3.8/socket.py", line 808, in create_connection
    raise err
  File "/cluster/home/atabin/miniconda3/envs/climatenet/lib/python3.8/socket.py", line 796, in create_connection
    sock.connect(sa)
OSError: [Errno 101] Network is unreachable

During handling of the above exception, another exception occurred:

Traceback (most recent call last):
  File "/cluster/home/atabin/ClimateNet_AI4Good/run.py", line 33, in <module>
    train.run(
  File "/cluster/home/atabin/ClimateNet_AI4Good/climatenet/train.py", line 14, in run
    model = Trainer(config, model_name)
  File "/cluster/home/atabin/ClimateNet_AI4Good/climatenet/models/trainer.py", line 71, in __init__
    self.network = MODELS[model_name](classes=len(self.config.labels), channels=len(list(self.config.fields))).cuda()
  File "/cluster/home/atabin/ClimateNet_AI4Good/climatenet/models/segnet/segnet.py", line 13, in __init__
    vgg_bn = models.vgg16_bn(pretrained= pretrained)
  File "/cluster/home/atabin/miniconda3/envs/climatenet/lib/python3.8/site-packages/torchvision/models/vgg.py", line 166, in vgg16_bn
    model.load_state_dict(model_zoo.load_url(model_urls['vgg16_bn']))
  File "/cluster/home/atabin/miniconda3/envs/climatenet/lib/python3.8/site-packages/torch/hub.py", line 731, in load_state_dict_from_url
    download_url_to_file(url, cached_file, hash_prefix, progress=progress)
  File "/cluster/home/atabin/miniconda3/envs/climatenet/lib/python3.8/site-packages/torch/hub.py", line 597, in download_url_to_file
    u = urlopen(req)
  File "/cluster/home/atabin/miniconda3/envs/climatenet/lib/python3.8/urllib/request.py", line 222, in urlopen
    return opener.open(url, data, timeout)
  File "/cluster/home/atabin/miniconda3/envs/climatenet/lib/python3.8/urllib/request.py", line 525, in open
    response = self._open(req, data)
  File "/cluster/home/atabin/miniconda3/envs/climatenet/lib/python3.8/urllib/request.py", line 542, in _open
    result = self._call_chain(self.handle_open, protocol, protocol +
  File "/cluster/home/atabin/miniconda3/envs/climatenet/lib/python3.8/urllib/request.py", line 502, in _call_chain
    result = func(*args)
  File "/cluster/home/atabin/miniconda3/envs/climatenet/lib/python3.8/urllib/request.py", line 1393, in https_open
    return self.do_open(http.client.HTTPSConnection, req,
  File "/cluster/home/atabin/miniconda3/envs/climatenet/lib/python3.8/urllib/request.py", line 1353, in do_open
    raise URLError(err)
urllib.error.URLError: <urlopen error [Errno 101] Network is unreachable>
Done!
