Running on euler with following parameters : 
User : atabin
Model : cgnet
Data folder : /cluster/work/igp_psr/ai4good/group-1b/data/
Saving directory : /cluster/scratch/atabin/cgnet/
Checkpoint path : /cluster/scratch/atabin/checkpoints/cgnet/
  0%|          | 0/8 [00:00<?, ?it/s]{'model': 'cgnet', 'data_dir': '/cluster/work/igp_psr/ai4good/group-1b/data/', 'checkpoint_path': '/cluster/scratch/atabin/checkpoints/cgnet/', 'save_dir': '/cluster/scratch/atabin/cgnet/'}
Running baseline example...
train_path :  /cluster/work/igp_psr/ai4good/group-1b/data/train/
val_path :  /cluster/work/igp_psr/ai4good/group-1b/data/val/
inference_path :  /cluster/work/igp_psr/ai4good/group-1b/data/test/
Loading data...
  0%|          | 0/8 [00:05<?, ?it/s]
Traceback (most recent call last):
  File "/cluster/home/atabin/ClimateNet_AI4Good/run.py", line 37, in <module>
    trained_cgnet.run(
  File "/cluster/home/atabin/ClimateNet_AI4Good/climatenet/trained_cgnet/trained_cgnet.py", line 32, in run
    cgnet.evaluate(inference)
  File "/cluster/home/atabin/ClimateNet_AI4Good/climatenet/models/cgnet.py", line 134, in evaluate
    for features, labels in epoch_loader:
  File "/cluster/home/atabin/miniconda3/envs/climatenet/lib/python3.8/site-packages/tqdm/std.py", line 1167, in __iter__
    for obj in iterable:
  File "/cluster/home/atabin/miniconda3/envs/climatenet/lib/python3.8/site-packages/torch/utils/data/dataloader.py", line 345, in __next__
    data = self._next_data()
  File "/cluster/home/atabin/miniconda3/envs/climatenet/lib/python3.8/site-packages/torch/utils/data/dataloader.py", line 856, in _next_data
    return self._process_data(data)
  File "/cluster/home/atabin/miniconda3/envs/climatenet/lib/python3.8/site-packages/torch/utils/data/dataloader.py", line 881, in _process_data
    data.reraise()
  File "/cluster/home/atabin/miniconda3/envs/climatenet/lib/python3.8/site-packages/torch/_utils.py", line 394, in reraise
    raise self.exc_type(msg)
ValueError: Caught ValueError in DataLoader worker process 0.
Original Traceback (most recent call last):
  File "/cluster/home/atabin/miniconda3/envs/climatenet/lib/python3.8/site-packages/torch/utils/data/_utils/worker.py", line 178, in _worker_loop
    data = fetcher.fetch(index)
  File "/cluster/home/atabin/miniconda3/envs/climatenet/lib/python3.8/site-packages/torch/utils/data/_utils/fetch.py", line 47, in fetch
    return self.collate_fn(data)
  File "/cluster/home/atabin/ClimateNet_AI4Good/climatenet/utils/data.py", line 73, in collate
    data, labels = map(list, zip(*batch))
ValueError: not enough values to unpack (expected 2, got 1)

Done!
